2025-03-15 11:28:53,057 - INFO - server listening on 0.0.0.0:8100
2025-03-15 11:28:53,057 - INFO - WebSocket server started on ws://0.0.0.0:8100
2025-03-15 11:32:03,872 - ERROR - opening handshake failed
Traceback (most recent call last):
  File "/root/venv/lib/python3.12/site-packages/websockets/http11.py", line 138, in parse
    request_line = yield from parse_line(read_line)
                   ^^^^^^^^^^^^^^^^^^^^^^^^^^^^^^^^
  File "/root/venv/lib/python3.12/site-packages/websockets/http11.py", line 314, in parse_line
    raise EOFError("line without CRLF")
EOFError: line without CRLF

The above exception was the direct cause of the following exception:

Traceback (most recent call last):
  File "/root/venv/lib/python3.12/site-packages/websockets/server.py", line 545, in parse
    request = yield from Request.parse(
              ^^^^^^^^^^^^^^^^^^^^^^^^^
  File "/root/venv/lib/python3.12/site-packages/websockets/http11.py", line 140, in parse
    raise EOFError("connection closed while reading HTTP request line") from exc
EOFError: connection closed while reading HTTP request line

The above exception was the direct cause of the following exception:

Traceback (most recent call last):
  File "/root/venv/lib/python3.12/site-packages/websockets/asyncio/server.py", line 356, in conn_handler
    await connection.handshake(
  File "/root/venv/lib/python3.12/site-packages/websockets/asyncio/server.py", line 207, in handshake
    raise self.protocol.handshake_exc
websockets.exceptions.InvalidMessage: did not receive a valid HTTP request
2025-03-15 11:32:14,123 - INFO - connection rejected (426 Upgrade Required)
2025-03-15 11:32:14,354 - ERROR - opening handshake failed
Traceback (most recent call last):
  File "/root/venv/lib/python3.12/site-packages/websockets/asyncio/server.py", line 356, in conn_handler
    await connection.handshake(
  File "/root/venv/lib/python3.12/site-packages/websockets/asyncio/server.py", line 207, in handshake
    raise self.protocol.handshake_exc
  File "/root/venv/lib/python3.12/site-packages/websockets/server.py", line 138, in accept
    ) = self.process_request(request)
        ^^^^^^^^^^^^^^^^^^^^^^^^^^^^^
  File "/root/venv/lib/python3.12/site-packages/websockets/server.py", line 233, in process_request
    raise InvalidUpgrade(
websockets.exceptions.InvalidUpgrade: missing Connection header
2025-03-15 11:32:35,500 - INFO - connection rejected (426 Upgrade Required)
2025-03-15 11:32:36,029 - ERROR - opening handshake failed
Traceback (most recent call last):
  File "/root/venv/lib/python3.12/site-packages/websockets/asyncio/server.py", line 356, in conn_handler
    await connection.handshake(
  File "/root/venv/lib/python3.12/site-packages/websockets/asyncio/server.py", line 207, in handshake
    raise self.protocol.handshake_exc
  File "/root/venv/lib/python3.12/site-packages/websockets/server.py", line 138, in accept
    ) = self.process_request(request)
        ^^^^^^^^^^^^^^^^^^^^^^^^^^^^^
  File "/root/venv/lib/python3.12/site-packages/websockets/server.py", line 233, in process_request
    raise InvalidUpgrade(
websockets.exceptions.InvalidUpgrade: missing Connection header
2025-03-15 12:46:15,270 - INFO - connection open
2025-03-15 12:46:15,291 - INFO - Received: Hello Server

2025-03-15 12:46:15,291 - INFO - Sent: Echo: Hello Server

