2025-03-13 17:09:29,665 - INFO - server listening on 0.0.0.0:8100
2025-03-13 17:09:29,665 - INFO - WebSocket server started on ws://0.0.0.0:8100
2025-03-13 17:11:04,963 - INFO - connection open
2025-03-13 17:11:05,177 - INFO - Received: Hello Server

2025-03-13 17:11:05,384 - ERROR - connection handler failed
Traceback (most recent call last):
  File "/root/venv/lib/python3.12/site-packages/websockets/asyncio/server.py", line 376, in conn_handler
    await self.handler(connection)
  File "/app/websockets_server.py", line 20, in echo
    await websocket.send(f"Echo: {message}")
  File "/root/venv/lib/python3.12/site-packages/websockets/asyncio/connection.py", line 476, in send
    async with self.send_context():
  File "/usr/lib/python3.12/contextlib.py", line 210, in __aenter__
    return await anext(self.gen)
           ^^^^^^^^^^^^^^^^^^^^^
  File "/root/venv/lib/python3.12/site-packages/websockets/asyncio/connection.py", line 957, in send_context
    raise self.protocol.close_exc from original_exc
websockets.exceptions.ConnectionClosedOK: received 1005 (no status received [internal]); then sent 1005 (no status received [internal])
