2025-03-25 09:42:52,464 - INFO - server listening on 0.0.0.0:8101
2025-03-25 09:42:52,464 - INFO - WebSocket server started on wss://0.0.0.0:8101
2025-03-25 09:49:32,905 - INFO - connection rejected (426 Upgrade Required)
2025-03-25 09:49:33,095 - ERROR - opening handshake failed
Traceback (most recent call last):
  File "/root/venv/lib/python3.12/site-packages/websockets/asyncio/server.py", line 356, in conn_handler
    await connection.handshake(
  File "/root/venv/lib/python3.12/site-packages/websockets/asyncio/server.py", line 207, in handshake
    raise self.protocol.handshake_exc
  File "/root/venv/lib/python3.12/site-packages/websockets/server.py", line 138, in accept
    ) = self.process_request(request)
        ^^^^^^^^^^^^^^^^^^^^^^^^^^^^^
  File "/root/venv/lib/python3.12/site-packages/websockets/server.py", line 233, in process_request
    raise InvalidUpgrade(
websockets.exceptions.InvalidUpgrade: missing Connection header
2025-03-25 09:50:00,103 - ERROR - opening handshake failed
Traceback (most recent call last):
  File "/root/venv/lib/python3.12/site-packages/websockets/http11.py", line 138, in parse
    request_line = yield from parse_line(read_line)
                   ^^^^^^^^^^^^^^^^^^^^^^^^^^^^^^^^
  File "/root/venv/lib/python3.12/site-packages/websockets/http11.py", line 309, in parse_line
    line = yield from read_line(MAX_LINE_LENGTH)
           ^^^^^^^^^^^^^^^^^^^^^^^^^^^^^^^^^^^^^
  File "/root/venv/lib/python3.12/site-packages/websockets/streams.py", line 46, in read_line
    raise EOFError(f"stream ends after {p} bytes, before end of line")
EOFError: stream ends after 0 bytes, before end of line

The above exception was the direct cause of the following exception:

Traceback (most recent call last):
  File "/root/venv/lib/python3.12/site-packages/websockets/server.py", line 545, in parse
    request = yield from Request.parse(
              ^^^^^^^^^^^^^^^^^^^^^^^^^
  File "/root/venv/lib/python3.12/site-packages/websockets/http11.py", line 140, in parse
    raise EOFError("connection closed while reading HTTP request line") from exc
EOFError: connection closed while reading HTTP request line

The above exception was the direct cause of the following exception:

Traceback (most recent call last):
  File "/root/venv/lib/python3.12/site-packages/websockets/asyncio/server.py", line 356, in conn_handler
    await connection.handshake(
  File "/root/venv/lib/python3.12/site-packages/websockets/asyncio/server.py", line 207, in handshake
    raise self.protocol.handshake_exc
websockets.exceptions.InvalidMessage: did not receive a valid HTTP request
2025-03-25 09:50:03,735 - INFO - connection rejected (426 Upgrade Required)
2025-03-25 09:50:04,181 - ERROR - opening handshake failed
Traceback (most recent call last):
  File "/root/venv/lib/python3.12/site-packages/websockets/asyncio/server.py", line 356, in conn_handler
    await connection.handshake(
  File "/root/venv/lib/python3.12/site-packages/websockets/asyncio/server.py", line 207, in handshake
    raise self.protocol.handshake_exc
  File "/root/venv/lib/python3.12/site-packages/websockets/server.py", line 138, in accept
    ) = self.process_request(request)
        ^^^^^^^^^^^^^^^^^^^^^^^^^^^^^
  File "/root/venv/lib/python3.12/site-packages/websockets/server.py", line 233, in process_request
    raise InvalidUpgrade(
websockets.exceptions.InvalidUpgrade: missing Connection header
2025-03-25 10:18:19,850 - INFO - connection open
2025-03-25 10:18:19,856 - INFO - Received: Hello Server

2025-03-25 10:18:19,857 - INFO - Sent: Echo: Hello Server

